[2022-09-21T23:22:31.473+0000] {taskinstance.py:1171} INFO - Dependencies all met for <TaskInstance: match_assembler.sheet_editor_task manual__2022-09-21T23:22:18.996658+00:00 [queued]>
[2022-09-21T23:22:31.480+0000] {taskinstance.py:1171} INFO - Dependencies all met for <TaskInstance: match_assembler.sheet_editor_task manual__2022-09-21T23:22:18.996658+00:00 [queued]>
[2022-09-21T23:22:31.480+0000] {taskinstance.py:1368} INFO - 
--------------------------------------------------------------------------------
[2022-09-21T23:22:31.480+0000] {taskinstance.py:1369} INFO - Starting attempt 1 of 1
[2022-09-21T23:22:31.480+0000] {taskinstance.py:1370} INFO - 
--------------------------------------------------------------------------------
[2022-09-21T23:22:31.491+0000] {taskinstance.py:1389} INFO - Executing <Task(SheetEditorOperator): sheet_editor_task> on 2022-09-21 23:22:18.996658+00:00
[2022-09-21T23:22:31.496+0000] {standard_task_runner.py:52} INFO - Started process 111 to run task
[2022-09-21T23:22:31.498+0000] {standard_task_runner.py:79} INFO - Running: ['***', 'tasks', 'run', 'match_assembler', 'sheet_editor_task', 'manual__2022-09-21T23:22:18.996658+00:00', '--job-id', '386', '--raw', '--subdir', 'DAGS_FOLDER/snitch/dag_builder.py', '--cfg-path', '/tmp/tmprrluhu9s', '--error-file', '/tmp/tmpmiutikr9']
[2022-09-21T23:22:31.499+0000] {standard_task_runner.py:80} INFO - Job 386: Subtask sheet_editor_task
[2022-09-21T23:22:31.544+0000] {task_command.py:371} INFO - Running <TaskInstance: match_assembler.sheet_editor_task manual__2022-09-21T23:22:18.996658+00:00 [running]> on host 0f5dc8100c36
[2022-09-21T23:22:31.600+0000] {taskinstance.py:1583} INFO - Exporting the following env vars:
AIRFLOW_CTX_DAG_EMAIL=bookly.beekly@gmail.com
AIRFLOW_CTX_DAG_OWNER=bookly
AIRFLOW_CTX_DAG_ID=match_assembler
AIRFLOW_CTX_TASK_ID=sheet_editor_task
AIRFLOW_CTX_EXECUTION_DATE=2022-09-21T23:22:18.996658+00:00
AIRFLOW_CTX_TRY_NUMBER=1
AIRFLOW_CTX_DAG_RUN_ID=manual__2022-09-21T23:22:18.996658+00:00
[2022-09-21T23:22:31.601+0000] {operators.py:124} INFO - ['logs', 'dags', '***-worker.pid', 'vars', 'plugins', '***.cfg', 'webserver_config.py']
[2022-09-21T23:22:31.601+0000] {taskinstance.py:1902} ERROR - Task failed with exception
Traceback (most recent call last):
  File "/home/airflow/.local/lib/python3.7/site-packages/airflow/operators/python.py", line 171, in execute
    return_value = self.execute_callable()
  File "/home/airflow/.local/lib/python3.7/site-packages/airflow/operators/python.py", line 189, in execute_callable
    return self.python_callable(*self.op_args, **self.op_kwargs)
  File "/opt/airflow/dags/snitch/operators.py", line 128, in edit_sheet
    SERVICE_ACCOUNT_FILE, scopes=SCOPES)
  File "/home/airflow/.local/lib/python3.7/site-packages/google/oauth2/service_account.py", line 239, in from_service_account_file
    filename, require=["client_email", "token_uri"]
  File "/home/airflow/.local/lib/python3.7/site-packages/google/auth/_service_account_info.py", line 79, in from_filename
    with io.open(filename, "r", encoding="utf-8") as json_file:
FileNotFoundError: [Errno 2] No such file or directory: 'vars/keys.json'
[2022-09-21T23:22:31.607+0000] {taskinstance.py:1412} INFO - Marking task as FAILED. dag_id=match_assembler, task_id=sheet_editor_task, execution_date=20220921T232218, start_date=20220921T232231, end_date=20220921T232231
[2022-09-21T23:22:31.729+0000] {warnings.py:110} WARNING - /home/***/.local/lib/python3.7/site-packages/***/utils/email.py:119: PendingDeprecationWarning: Fetching SMTP credentials from configuration variables will be deprecated in a future release. Please set credentials using a connection instead.
  send_mime_email(e_from=mail_from, e_to=recipients, mime_msg=msg, conn_id=conn_id, dryrun=dryrun)

[2022-09-21T23:22:31.729+0000] {configuration.py:562} WARNING - section/key [smtp/smtp_user] not found in config
[2022-09-21T23:22:31.729+0000] {email.py:228} INFO - Email alerting: attempt 1
[2022-09-21T23:22:31.733+0000] {configuration.py:562} WARNING - section/key [smtp/smtp_user] not found in config
[2022-09-21T23:22:31.733+0000] {email.py:228} INFO - Email alerting: attempt 1
[2022-09-21T23:22:31.734+0000] {taskinstance.py:1957} ERROR - Failed to send email to: ['bookly.beekly@gmail.com']
Traceback (most recent call last):
  File "/home/airflow/.local/lib/python3.7/site-packages/airflow/models/taskinstance.py", line 1463, in _run_raw_task
    self._execute_task_with_callbacks(context, test_mode)
  File "/home/airflow/.local/lib/python3.7/site-packages/airflow/models/taskinstance.py", line 1610, in _execute_task_with_callbacks
    result = self._execute_task(context, task_orig)
  File "/home/airflow/.local/lib/python3.7/site-packages/airflow/models/taskinstance.py", line 1671, in _execute_task
    result = execute_callable(context=context)
  File "/home/airflow/.local/lib/python3.7/site-packages/airflow/operators/python.py", line 171, in execute
    return_value = self.execute_callable()
  File "/home/airflow/.local/lib/python3.7/site-packages/airflow/operators/python.py", line 189, in execute_callable
    return self.python_callable(*self.op_args, **self.op_kwargs)
  File "/opt/airflow/dags/snitch/operators.py", line 128, in edit_sheet
    SERVICE_ACCOUNT_FILE, scopes=SCOPES)
  File "/home/airflow/.local/lib/python3.7/site-packages/google/oauth2/service_account.py", line 239, in from_service_account_file
    filename, require=["client_email", "token_uri"]
  File "/home/airflow/.local/lib/python3.7/site-packages/google/auth/_service_account_info.py", line 79, in from_filename
    with io.open(filename, "r", encoding="utf-8") as json_file:
FileNotFoundError: [Errno 2] No such file or directory: 'vars/keys.json'

During handling of the above exception, another exception occurred:

Traceback (most recent call last):
  File "/home/airflow/.local/lib/python3.7/site-packages/airflow/models/taskinstance.py", line 2339, in email_alert
    send_email(task.email, subject, html_content)
  File "/home/airflow/.local/lib/python3.7/site-packages/airflow/utils/email.py", line 71, in send_email
    **kwargs,
  File "/home/airflow/.local/lib/python3.7/site-packages/airflow/utils/email.py", line 119, in send_email_smtp
    send_mime_email(e_from=mail_from, e_to=recipients, mime_msg=msg, conn_id=conn_id, dryrun=dryrun)
  File "/home/airflow/.local/lib/python3.7/site-packages/airflow/utils/email.py", line 230, in send_mime_email
    smtp_conn = _get_smtp_connection(smtp_host, smtp_port, smtp_timeout, smtp_ssl)
  File "/home/airflow/.local/lib/python3.7/site-packages/airflow/utils/email.py", line 264, in _get_smtp_connection
    else smtplib.SMTP(host=host, port=port, timeout=timeout)
  File "/usr/local/lib/python3.7/smtplib.py", line 251, in __init__
    (code, msg) = self.connect(host, port)
  File "/usr/local/lib/python3.7/smtplib.py", line 336, in connect
    self.sock = self._get_socket(host, port, self.timeout)
  File "/usr/local/lib/python3.7/smtplib.py", line 307, in _get_socket
    self.source_address)
  File "/usr/local/lib/python3.7/socket.py", line 728, in create_connection
    raise err
  File "/usr/local/lib/python3.7/socket.py", line 716, in create_connection
    sock.connect(sa)
OSError: [Errno 99] Cannot assign requested address

During handling of the above exception, another exception occurred:

Traceback (most recent call last):
  File "/home/airflow/.local/lib/python3.7/site-packages/airflow/models/taskinstance.py", line 1955, in handle_failure
    self.email_alert(error, task)
  File "/home/airflow/.local/lib/python3.7/site-packages/airflow/models/taskinstance.py", line 2341, in email_alert
    send_email(task.email, subject, html_content_err)
  File "/home/airflow/.local/lib/python3.7/site-packages/airflow/utils/email.py", line 71, in send_email
    **kwargs,
  File "/home/airflow/.local/lib/python3.7/site-packages/airflow/utils/email.py", line 119, in send_email_smtp
    send_mime_email(e_from=mail_from, e_to=recipients, mime_msg=msg, conn_id=conn_id, dryrun=dryrun)
  File "/home/airflow/.local/lib/python3.7/site-packages/airflow/utils/email.py", line 230, in send_mime_email
    smtp_conn = _get_smtp_connection(smtp_host, smtp_port, smtp_timeout, smtp_ssl)
  File "/home/airflow/.local/lib/python3.7/site-packages/airflow/utils/email.py", line 264, in _get_smtp_connection
    else smtplib.SMTP(host=host, port=port, timeout=timeout)
  File "/usr/local/lib/python3.7/smtplib.py", line 251, in __init__
    (code, msg) = self.connect(host, port)
  File "/usr/local/lib/python3.7/smtplib.py", line 336, in connect
    self.sock = self._get_socket(host, port, self.timeout)
  File "/usr/local/lib/python3.7/smtplib.py", line 307, in _get_socket
    self.source_address)
  File "/usr/local/lib/python3.7/socket.py", line 728, in create_connection
    raise err
  File "/usr/local/lib/python3.7/socket.py", line 716, in create_connection
    sock.connect(sa)
OSError: [Errno 99] Cannot assign requested address
[2022-09-21T23:22:31.744+0000] {standard_task_runner.py:97} ERROR - Failed to execute job 386 for task sheet_editor_task ([Errno 2] No such file or directory: 'vars/keys.json'; 111)
[2022-09-21T23:22:31.789+0000] {local_task_job.py:156} INFO - Task exited with return code 1
[2022-09-21T23:22:31.814+0000] {local_task_job.py:279} INFO - 0 downstream tasks scheduled from follow-on schedule check
