[2022-09-21T23:25:24.730+0000] {taskinstance.py:1171} INFO - Dependencies all met for <TaskInstance: match_assembler.sheet_editor_task manual__2022-09-21T23:25:12.736040+00:00 [queued]>
[2022-09-21T23:25:24.737+0000] {taskinstance.py:1171} INFO - Dependencies all met for <TaskInstance: match_assembler.sheet_editor_task manual__2022-09-21T23:25:12.736040+00:00 [queued]>
[2022-09-21T23:25:24.737+0000] {taskinstance.py:1368} INFO - 
--------------------------------------------------------------------------------
[2022-09-21T23:25:24.738+0000] {taskinstance.py:1369} INFO - Starting attempt 1 of 1
[2022-09-21T23:25:24.738+0000] {taskinstance.py:1370} INFO - 
--------------------------------------------------------------------------------
[2022-09-21T23:25:24.749+0000] {taskinstance.py:1389} INFO - Executing <Task(SheetEditorOperator): sheet_editor_task> on 2022-09-21 23:25:12.736040+00:00
[2022-09-21T23:25:24.753+0000] {standard_task_runner.py:52} INFO - Started process 110 to run task
[2022-09-21T23:25:24.755+0000] {standard_task_runner.py:79} INFO - Running: ['***', 'tasks', 'run', 'match_assembler', 'sheet_editor_task', 'manual__2022-09-21T23:25:12.736040+00:00', '--job-id', '392', '--raw', '--subdir', 'DAGS_FOLDER/snitch/dag_builder.py', '--cfg-path', '/tmp/tmp008_zme2', '--error-file', '/tmp/tmpi7e_p876']
[2022-09-21T23:25:24.756+0000] {standard_task_runner.py:80} INFO - Job 392: Subtask sheet_editor_task
[2022-09-21T23:25:24.799+0000] {task_command.py:371} INFO - Running <TaskInstance: match_assembler.sheet_editor_task manual__2022-09-21T23:25:12.736040+00:00 [running]> on host 0f5dc8100c36
[2022-09-21T23:25:24.856+0000] {taskinstance.py:1583} INFO - Exporting the following env vars:
AIRFLOW_CTX_DAG_EMAIL=bookly.beekly@gmail.com
AIRFLOW_CTX_DAG_OWNER=bookly
AIRFLOW_CTX_DAG_ID=match_assembler
AIRFLOW_CTX_TASK_ID=sheet_editor_task
AIRFLOW_CTX_EXECUTION_DATE=2022-09-21T23:25:12.736040+00:00
AIRFLOW_CTX_TRY_NUMBER=1
AIRFLOW_CTX_DAG_RUN_ID=manual__2022-09-21T23:25:12.736040+00:00
[2022-09-21T23:25:24.857+0000] {operators.py:124} INFO - ['logs', 'dags', '***-worker.pid', 'vars', 'plugins', '***.cfg', 'webserver_config.py']
[2022-09-21T23:25:24.865+0000] {__init__.py:48} WARNING - file_cache is unavailable when using oauth2client >= 4.0.0 or google-auth
Traceback (most recent call last):
  File "/home/airflow/.local/lib/python3.7/site-packages/googleapiclient/discovery_cache/file_cache.py", line 33, in <module>
    from oauth2client.contrib.locked_file import LockedFile
ModuleNotFoundError: No module named 'oauth2client'

During handling of the above exception, another exception occurred:

Traceback (most recent call last):
  File "/home/airflow/.local/lib/python3.7/site-packages/googleapiclient/discovery_cache/file_cache.py", line 37, in <module>
    from oauth2client.locked_file import LockedFile
ModuleNotFoundError: No module named 'oauth2client'

During handling of the above exception, another exception occurred:

Traceback (most recent call last):
  File "/home/airflow/.local/lib/python3.7/site-packages/googleapiclient/discovery_cache/__init__.py", line 44, in autodetect
    from . import file_cache
  File "/home/airflow/.local/lib/python3.7/site-packages/googleapiclient/discovery_cache/file_cache.py", line 41, in <module>
    "file_cache is unavailable when using oauth2client >= 4.0.0 or google-auth"
ImportError: file_cache is unavailable when using oauth2client >= 4.0.0 or google-auth
[2022-09-21T23:25:26.429+0000] {operators.py:143} INFO - []
[2022-09-21T23:25:26.852+0000] {operators.py:150} INFO - {'spreadsheetId': '1iGYmQJkirhmfW0NW13_xd51pVmxk7iBH27dDLI_syds', 'updatedRange': 'Sheet2!A1:B3', 'updatedRows': 3, 'updatedColumns': 2, 'updatedCells': 6}
[2022-09-21T23:25:26.852+0000] {python.py:173} INFO - Done. Returned value was: None
[2022-09-21T23:25:26.862+0000] {taskinstance.py:1412} INFO - Marking task as SUCCESS. dag_id=match_assembler, task_id=sheet_editor_task, execution_date=20220921T232512, start_date=20220921T232524, end_date=20220921T232526
[2022-09-21T23:25:26.891+0000] {local_task_job.py:156} INFO - Task exited with return code 0
[2022-09-21T23:25:26.918+0000] {local_task_job.py:279} INFO - 0 downstream tasks scheduled from follow-on schedule check
